Workbook

Sheet Instrucciones
A1: Encuesta de clima laboral — Djanter Capital
A2: Gratuita. djantercapital.cl/recursos/encuesta-clima-laboral/
A4: 1. Crea un formulario anónimo (Google Forms o Microsoft Forms, sin recolectar correos) con las preguntas de la hoja 'Preguntas'.
A5: 2. Exporta las respuestas y pega los valores de 1 a 5 en la hoja 'Respuestas', una fila por persona, desde la columna B (P1) a la AG (P32).
A6: 3. No inviertas tú las preguntas marcadas (I): la hoja 'Resultados' las corrige sola con 6 - respuesta.
A7: 4. La hoja 'Resultados' calcula el % favorable (respuestas 4 y 5), el % desfavorable (1 y 2) y el promedio por pregunta y por dimensión.
A8: 5. Para resultados por área, copia el archivo y pega solo las respuestas de esa área. No informes grupos con menos de 5 respuestas.
A10: Importante: cuestionario base inspirado en las dimensiones clásicas de clima (Litwin y Stringer, 1968). No es un instrumento psicométricamente validado
A11: ni reemplaza al CEAL-SM/SUSESO de riesgos psicosociales.
A12: Escala: 1 Muy en desacuerdo · 2 En desacuerdo · 3 Ni de acuerdo ni en desacuerdo · 4 De acuerdo · 5 Muy de acuerdo.

Sheet Preguntas
A1: N.º | B1: Dimensión | C1: Afirmación | D1: Inversa
A2: 1 | B2: Liderazgo de la jefatura directa | C2: Mi jefatura me da orientaciones claras sobre lo que espera de mi trabajo.
A3: 2 | B3: Liderazgo de la jefatura directa | C3: Mi jefatura me entrega retroalimentación útil sobre mi desempeño.
A4: 3 | B4: Liderazgo de la jefatura directa | C4: Mi jefatura trata a todas las personas del equipo con respeto.
A5: 4 | B5: Liderazgo de la jefatura directa | C5: Siento que puedo plantearle un problema a mi jefatura sin temor a represalias.
A6: 5 | B6: Comunicación | C6: Me entero a tiempo de las decisiones que afectan mi trabajo.
A7: 6 | B7: Comunicación | C7: La información llega de manera clara entre las distintas áreas.
A8: 7 | B8: Comunicación | C8: Con frecuencia me entero de cosas importantes por rumores. | D8: Sí
A9: 8 | B9: Comunicación | C9: Cuando doy una opinión o sugerencia, siento que es considerada.
A10: 9 | B10: Relaciones y trabajo en equipo | C10: En mi equipo nos ayudamos cuando alguien lo necesita.
A11: 10 | B11: Relaciones y trabajo en equipo | C11: Las relaciones con mis compañeros son de respeto.
A12: 11 | B12: Relaciones y trabajo en equipo | C12: Los conflictos en mi equipo se conversan y se resuelven.
A13: 12 | B13: Relaciones y trabajo en equipo | C13: Existe colaboración entre mi área y las demás áreas.
A14: 13 | B14: Reconocimiento | C14: Cuando hago bien mi trabajo, se reconoce.
A15: 14 | B15: Reconocimiento | C15: Siento que mi remuneración es justa en relación con mi trabajo.
A16: 15 | B16: Reconocimiento | C16: Los criterios para reconocer o premiar a las personas son claros.
A17: 16 | B17: Reconocimiento | C17: Siento que mi esfuerzo pasa desapercibido. | D17: Sí
A18: 17 | B18: Carga y organización del trabajo | C18: Puedo realizar mi trabajo dentro de mi jornada habitual.
A19: 18 | B19: Carga y organización del trabajo | C19: La carga de trabajo está bien distribuida en mi equipo.
A20: 19 | B20: Carga y organización del trabajo | C20: Con frecuencia tengo que trabajar con plazos imposibles de cumplir. | D20: Sí
A21: 20 | B21: Carga y organización del trabajo | C21: Puedo compatibilizar mi trabajo con mi vida personal.
A22: 21 | B22: Condiciones y recursos | C22: Cuento con los materiales y equipos necesarios para hacer bien mi trabajo.
A23: 22 | B23: Condiciones y recursos | C23: Mi lugar de trabajo es seguro.
A24: 23 | B24: Condiciones y recursos | C24: Mi lugar de trabajo tiene condiciones adecuadas (espacio, ruido, temperatura).
A25: 24 | B25: Condiciones y recursos | C25: Los sistemas y procedimientos facilitan mi trabajo.
A26: 25 | B26: Claridad del rol y desarrollo | C26: Tengo claras mis funciones y responsabilidades.
A27: 26 | B27: Claridad del rol y desarrollo | C27: He recibido la capacitación necesaria para hacer bien mi trabajo.
A28: 27 | B28: Claridad del rol y desarrollo | C28: En esta organización tengo oportunidades de aprender y crecer.
A29: 28 | B29: Claridad del rol y desarrollo | C29: Los ascensos y cambios de cargo se deciden con criterios claros.
A30: 29 | B30: Compromiso y pertenencia | C30: Me siento orgulloso u orgullosa de trabajar en esta organización.
A31: 30 | B31: Compromiso y pertenencia | C31: Recomendaría esta organización como un buen lugar para trabajar.
A32: 31 | B32: Compromiso y pertenencia | C32: Pienso seguido en buscar trabajo en otra parte. | D32: Sí
A33: 32 | B33: Compromiso y pertenencia | C33: Entiendo cómo mi trabajo contribuye a los objetivos de la organización.
C35: Abierta 1: ¿Qué es lo que más valoras de trabajar aquí?
C36: Abierta 2: Si pudieras cambiar una sola cosa para mejorar el clima de tu equipo, ¿cuál sería?

Sheet Respuestas
A1: Persona | B1: P1 | C1: P2 | D1: P3 | E1: P4 | F1: P5 | G1: P6 | H1: P7 | I1: P8 | J1: P9 | K1: P10 | L1: P11 | M1: P12 | N1: P13 | O1: P14 | P1: P15 | Q1: P16 | R1: P17 | S1: P18 | T1: P19 | U1: P20 | V1: P21 | W1: P22 | X1: P23 | Y1: P24 | Z1: P25 | AA1: P26 | AB1: P27 | AC1: P28 | AD1: P29 | AE1: P30 | AF1: P31 | AG1: P32
A2: 1
A3: 2
A4: 3
A5: 4
A6: 5
A7: 6
A8: 7
A9: 8
A10: 9
A11: 10
A12: 11
A13: 12
... A501: 500

Sheet Resultados
A1: N.º | B1: Dimensión | C1: Afirmación | D1: Respuestas | E1: % favorable | F1: % desfavorable | G1: Promedio (corregido)
A2: 1 | B2: Liderazgo de la jefatura directa | C2: Mi jefatura me da orientaciones claras sobre lo que espera de mi trabajo. | D2: =COUNT(Respuestas!B2:B501) | E2: =IFERROR(COUNTIF(Respuestas!B2:B501,">=4")/D2,"") | F2: =IFERROR(COUNTIF(Respuestas!B2:B501,"<=2")/D2,"") | G2: =IFERROR(AVERAGE(Respuestas!B2:B501),"")
A3: 2 | B3: Liderazgo de la jefatura directa | C3: Mi jefatura me entrega retroalimentación útil sobre mi desempeño. | D3: =COUNT(Respuestas!C2:C501) | E3: =IFERROR(COUNTIF(Respuestas!C2:C501,">=4")/D3,"") | F3: =IFERROR(COUNTIF(Respuestas!C2:C501,"<=2")/D3,"") | G3: =IFERROR(AVERAGE(Respuestas!C2:C501),"")
A4: 3 | B4: Liderazgo de la jefatura directa | C4: Mi jefatura trata a todas las personas del equipo con respeto. | D4: =COUNT(Respuestas!D2:D501) | E4: =IFERROR(COUNTIF(Respuestas!D2:D501,">=4")/D4,"") | F4: =IFERROR(COUNTIF(Respuestas!D2:D501,"<=2")/D4,"") | G4: =IFERROR(AVERAGE(Respuestas!D2:D501),"")
A5: 4 | B5: Liderazgo de la jefatura directa | C5: Siento que puedo plantearle un problema a mi jefatura sin temor a represalias. | D5: =COUNT(Respuestas!E2:E501) | E5: =IFERROR(COUNTIF(Respuestas!E2:E501,">=4")/D5,"") | F5: =IFERROR(COUNTIF(Respuestas!E2:E501,"<=2")/D5,"") | G5: =IFERROR(AVERAGE(Respuestas!E2:E501),"")
A6: 5 | B6: Comunicación | C6: Me entero a tiempo de las decisiones que afectan mi trabajo. | D6: =COUNT(Respuestas!F2:F501) | E6: =IFERROR(COUNTIF(Respuestas!F2:F501,">=4")/D6,"") | F6: =IFERROR(COUNTIF(Respuestas!F2:F501,"<=2")/D6,"") | G6: =IFERROR(AVERAGE(Respuestas!F2:F501),"")
A7: 6 | B7: Comunicación | C7: La información llega de manera clara entre las distintas áreas. | D7: =COUNT(Respuestas!G2:G501) | E7: =IFERROR(COUNTIF(Respuestas!G2:G501,">=4")/D7,"") | F7: =IFERROR(COUNTIF(Respuestas!G2:G501,"<=2")/D7,"") | G7: =IFERROR(AVERAGE(Respuestas!G2:G501),"")
A8: 7 | B8: Comunicación | C8: Con frecuencia me entero de cosas importantes por rumores. (I) | D8: =COUNT(Respuestas!H2:H501) | E8: =IFERROR(COUNTIF(Respuestas!H2:H501,"<=2")/D8,"") | F8: =IFERROR(COUNTIF(Respuestas!H2:H501,">=4")/D8,"") | G8: =IFERROR(6-AVERAGE(Respuestas!H2:H501),"")
A9: 8 | B9: Comunicación | C9: Cuando doy una opinión o sugerencia, siento que es considerada. | D9: =COUNT(Respuestas!I2:I501) | E9: =IFERROR(COUNTIF(Respuestas!I2:I501,">=4")/D9,"") | F9: =IFERROR(COUNTIF(Respuestas!I2:I501,"<=2")/D9,"") | G9: =IFERROR(AVERAGE(Respuestas!I2:I501),"")
A10: 9 | B10: Relaciones y trabajo en equipo | C10: En mi equipo nos ayudamos cuando alguien lo necesita. | D10: =COUNT(Respuestas!J2:J501) | E10: =IFERROR(COUNTIF(Respuestas!J2:J501,">=4")/D10,"") | F10: =IFERROR(COUNTIF(Respuestas!J2:J501,"<=2")/D10,"") | G10: =IFERROR(AVERAGE(Respuestas!J2:J501),"")
A11: 10 | B11: Relaciones y trabajo en equipo | C11: Las relaciones con mis compañeros son de respeto. | D11: =COUNT(Respuestas!K2:K501) | E11: =IFERROR(COUNTIF(Respuestas!K2:K501,">=4")/D11,"") | F11: =IFERROR(COUNTIF(Respuestas!K2:K501,"<=2")/D11,"") | G11: =IFERROR(AVERAGE(Respuestas!K2:K501),"")
A12: 11 | B12: Relaciones y trabajo en equipo | C12: Los conflictos en mi equipo se conversan y se resuelven. | D12: =COUNT(Respuestas!L2:L501) | E12: =IFERROR(COUNTIF(Respuestas!L2:L501,">=4")/D12,"") | F12: =IFERROR(COUNTIF(Respuestas!L2:L501,"<=2")/D12,"") | G12: =IFERROR(AVERAGE(Respuestas!L2:L501),"")
A13: 12 | B13: Relaciones y trabajo en equipo | C13: Existe colaboración entre mi área y las demás áreas. | D13: =COUNT(Respuestas!M2:M501) | E13: =IFERROR(COUNTIF(Respuestas!M2:M501,">=4")/D13,"") | F13: =IFERROR(COUNTIF(Respuestas!M2:M501,"<=2")/D13,"") | G13: =IFERROR(AVERAGE(Respuestas!M2:M501),"")
A14: 13 | B14: Reconocimiento | C14: Cuando hago bien mi trabajo, se reconoce. | D14: =COUNT(Respuestas!N2:N501) | E14: =IFERROR(COUNTIF(Respuestas!N2:N501,">=4")/D14,"") | F14: =IFERROR(COUNTIF(Respuestas!N2:N501,"<=2")/D14,"") | G14: =IFERROR(AVERAGE(Respuestas!N2:N501),"")
A15: 14 | B15: Reconocimiento | C15: Siento que mi remuneración es justa en relación con mi trabajo. | D15: =COUNT(Respuestas!O2:O501) | E15: =IFERROR(COUNTIF(Respuestas!O2:O501,">=4")/D15,"") | F15: =IFERROR(COUNTIF(Respuestas!O2:O501,"<=2")/D15,"") | G15: =IFERROR(AVERAGE(Respuestas!O2:O501),"")
A16: 15 | B16: Reconocimiento | C16: Los criterios para reconocer o premiar a las personas son claros. | D16: =COUNT(Respuestas!P2:P501) | E16: =IFERROR(COUNTIF(Respuestas!P2:P501,">=4")/D16,"") | F16: =IFERROR(COUNTIF(Respuestas!P2:P501,"<=2")/D16,"") | G16: =IFERROR(AVERAGE(Respuestas!P2:P501),"")
A17: 16 | B17: Reconocimiento | C17: Siento que mi esfuerzo pasa desapercibido. (I) | D17: =COUNT(Respuestas!Q2:Q501) | E17: =IFERROR(COUNTIF(Respuestas!Q2:Q501,"<=2")/D17,"") | F17: =IFERROR(COUNTIF(Respuestas!Q2:Q501,">=4")/D17,"") | G17: =IFERROR(6-AVERAGE(Respuestas!Q2:Q501),"")
A18: 17 | B18: Carga y organización del trabajo | C18: Puedo realizar mi trabajo dentro de mi jornada habitual. | D18: =COUNT(Respuestas!R2:R501) | E18: =IFERROR(COUNTIF(Respuestas!R2:R501,">=4")/D18,"") | F18: =IFERROR(COUNTIF(Respuestas!R2:R501,"<=2")/D18,"") | G18: =IFERROR(AVERAGE(Respuestas!R2:R501),"")
A19: 18 | B19: Carga y organización del trabajo | C19: La carga de trabajo está bien distribuida en mi equipo. | D19: =COUNT(Respuestas!S2:S501) | E19: =IFERROR(COUNTIF(Respuestas!S2:S501,">=4")/D19,"") | F19: =IFERROR(COUNTIF(Respuestas!S2:S501,"<=2")/D19,"") | G19: =IFERROR(AVERAGE(Respuestas!S2:S501),"")
A20: 19 | B20: Carga y organización del trabajo | C20: Con frecuencia tengo que trabajar con plazos imposibles de cumplir. (I) | D20: =COUNT(Respuestas!T2:T501) | E20: =IFERROR(COUNTIF(Respuestas!T2:T501,"<=2")/D20,"") | F20: =IFERROR(COUNTIF(Respuestas!T2:T501,">=4")/D20,"") | G20: =IFERROR(6-AVERAGE(Respuestas!T2:T501),"")
A21: 20 | B21: Carga y organización del trabajo | C21: Puedo compatibilizar mi trabajo con mi vida personal. | D21: =COUNT(Respuestas!U2:U501) | E21: =IFERROR(COUNTIF(Respuestas!U2:U501,">=4")/D21,"") | F21: =IFERROR(COUNTIF(Respuestas!U2:U501,"<=2")/D21,"") | G21: =IFERROR(AVERAGE(Respuestas!U2:U501),"")
A22: 21 | B22: Condiciones y recursos | C22: Cuento con los materiales y equipos necesarios para hacer bien mi trabajo. | D22: =COUNT(Respuestas!V2:V501) | E22: =IFERROR(COUNTIF(Respuestas!V2:V501,">=4")/D22,"") | F22: =IFERROR(COUNTIF(Respuestas!V2:V501,"<=2")/D22,"") | G22: =IFERROR(AVERAGE(Respuestas!V2:V501),"")
A23: 22 | B23: Condiciones y recursos | C23: Mi lugar de trabajo es seguro. | D23: =COUNT(Respuestas!W2:W501) | E23: =IFERROR(COUNTIF(Respuestas!W2:W501,">=4")/D23,"") | F23: =IFERROR(COUNTIF(Respuestas!W2:W501,"<=2")/D23,"") | G23: =IFERROR(AVERAGE(Respuestas!W2:W501),"")
A24: 23 | B24: Condiciones y recursos | C24: Mi lugar de trabajo tiene condiciones adecuadas (espacio, ruido, temperatura). | D24: =COUNT(Respuestas!X2:X501) | E24: =IFERROR(COUNTIF(Respuestas!X2:X501,">=4")/D24,"") | F24: =IFERROR(COUNTIF(Respuestas!X2:X501,"<=2")/D24,"") | G24: =IFERROR(AVERAGE(Respuestas!X2:X501),"")
A25: 24 | B25: Condiciones y recursos | C25: Los sistemas y procedimientos facilitan mi trabajo. | D25: =COUNT(Respuestas!Y2:Y501) | E25: =IFERROR(COUNTIF(Respuestas!Y2:Y501,">=4")/D25,"") | F25: =IFERROR(COUNTIF(Respuestas!Y2:Y501,"<=2")/D25,"") | G25: =IFERROR(AVERAGE(Respuestas!Y2:Y501),"")
A26: 25 | B26: Claridad del rol y desarrollo | C26: Tengo claras mis funciones y responsabilidades. | D26: =COUNT(Respuestas!Z2:Z501) | E26: =IFERROR(COUNTIF(Respuestas!Z2:Z501,">=4")/D26,"") | F26: =IFERROR(COUNTIF(Respuestas!Z2:Z501,"<=2")/D26,"") | G26: =IFERROR(AVERAGE(Respuestas!Z2:Z501),"")
A27: 26 | B27: Claridad del rol y desarrollo | C27: He recibido la capacitación necesaria para hacer bien mi trabajo. | D27: =COUNT(Respuestas!AA2:AA501) | E27: =IFERROR(COUNTIF(Respuestas!AA2:AA501,">=4")/D27,"") | F27: =IFERROR(COUNTIF(Respuestas!AA2:AA501,"<=2")/D27,"") | G27: =IFERROR(AVERAGE(Respuestas!AA2:AA501),"")
A28: 27 | B28: Claridad del rol y desarrollo | C28: En esta organización tengo oportunidades de aprender y crecer. | D28: =COUNT(Respuestas!AB2:AB501) | E28: =IFERROR(COUNTIF(Respuestas!AB2:AB501,">=4")/D28,"") | F28: =IFERROR(COUNTIF(Respuestas!AB2:AB501,"<=2")/D28,"") | G28: =IFERROR(AVERAGE(Respuestas!AB2:AB501),"")
A29: 28 | B29: Claridad del rol y desarrollo | C29: Los ascensos y cambios de cargo se deciden con criterios claros. | D29: =COUNT(Respuestas!AC2:AC501) | E29: =IFERROR(COUNTIF(Respuestas!AC2:AC501,">=4")/D29,"") | F29: =IFERROR(COUNTIF(Respuestas!AC2:AC501,"<=2")/D29,"") | G29: =IFERROR(AVERAGE(Respuestas!AC2:AC501),"")
A30: 29 | B30: Compromiso y pertenencia | C30: Me siento orgulloso u orgullosa de trabajar en esta organización. | D30: =COUNT(Respuestas!AD2:AD501) | E30: =IFERROR(COUNTIF(Respuestas!AD2:AD501,">=4")/D30,"") | F30: =IFERROR(COUNTIF(Respuestas!AD2:AD501,"<=2")/D30,"") | G30: =IFERROR(AVERAGE(Respuestas!AD2:AD501),"")
A31: 30 | B31: Compromiso y pertenencia | C31: Recomendaría esta organización como un buen lugar para trabajar. | D31: =COUNT(Respuestas!AE2:AE501) | E31: =IFERROR(COUNTIF(Respuestas!AE2:AE501,">=4")/D31,"") | F31: =IFERROR(COUNTIF(Respuestas!AE2:AE501,"<=2")/D31,"") | G31: =IFERROR(AVERAGE(Respuestas!AE2:AE501),"")
A32: 31 | B32: Compromiso y pertenencia | C32: Pienso seguido en buscar trabajo en otra parte. (I) | D32: =COUNT(Respuestas!AF2:AF501) | E32: =IFERROR(COUNTIF(Respuestas!AF2:AF501,"<=2")/D32,"") | F32: =IFERROR(COUNTIF(Respuestas!AF2:AF501,">=4")/D32,"") | G32: =IFERROR(6-AVERAGE(Respuestas!AF2:AF501),"")
A33: 32 | B33: Compromiso y pertenencia | C33: Entiendo cómo mi trabajo contribuye a los objetivos de la organización. | D33: =COUNT(Respuestas!AG2:AG501) | E33: =IFERROR(COUNTIF(Respuestas!AG2:AG501,">=4")/D33,"") | F33: =IFERROR(COUNTIF(Respuestas!AG2:AG501,"<=2")/D33,"") | G33: =IFERROR(AVERAGE(Respuestas!AG2:AG501),"")
B36: Dimensión | E36: % favorable | F36: % desfavorable | G36: Promedio
B37: Liderazgo de la jefatura directa | E37: =IFERROR(AVERAGE(E2:E5),"") | F37: =IFERROR(AVERAGE(F2:F5),"") | G37: =IFERROR(AVERAGE(G2:G5),"")
B38: Comunicación | E38: =IFERROR(AVERAGE(E6:E9),"") | F38: =IFERROR(AVERAGE(F6:F9),"") | G38: =IFERROR(AVERAGE(G6:G9),"")
B39: Relaciones y trabajo en equipo | E39: =IFERROR(AVERAGE(E10:E13),"") | F39: =IFERROR(AVERAGE(F10:F13),"") | G39: =IFERROR(AVERAGE(G10:G13),"")
B40: Reconocimiento | E40: =IFERROR(AVERAGE(E14:E17),"") | F40: =IFERROR(AVERAGE(F14:F17),"") | G40: =IFERROR(AVERAGE(G14:G17),"")
B41: Carga y organización del trabajo | E41: =IFERROR(AVERAGE(E18:E21),"") | F41: =IFERROR(AVERAGE(F18:F21),"") | G41: =IFERROR(AVERAGE(G18:G21),"")
B42: Condiciones y recursos | E42: =IFERROR(AVERAGE(E22:E25),"") | F42: =IFERROR(AVERAGE(F22:F25),"") | G42: =IFERROR(AVERAGE(G22:G25),"")
...
